
2021-05-22 22:38:52,550 INFO: errors [in D:\Documents\Udacity\Full Stack\projects\fyyur\app.py:538]
2021-05-22 22:41:46,506 INFO: errors [in D:\Documents\Udacity\Full Stack\projects\fyyur\app.py:538]
2021-05-22 22:48:08,226 INFO: errors [in D:\Documents\Udacity\Full Stack\projects\fyyur\app.py:543]
2021-05-22 22:48:12,084 ERROR: Exception on /venues [GET] [in d:\documents\udacity\full stack\projects\fyyur\env\lib\site-packages\flask\app.py:1440]
Traceback (most recent call last):
  File "d:\documents\udacity\full stack\projects\fyyur\env\lib\site-packages\flask\app.py", line 2051, in wsgi_app
    response = self.full_dispatch_request()
  File "d:\documents\udacity\full stack\projects\fyyur\env\lib\site-packages\flask\app.py", line 1501, in full_dispatch_request
    rv = self.handle_user_exception(e)
  File "d:\documents\udacity\full stack\projects\fyyur\env\lib\site-packages\flask\app.py", line 1499, in full_dispatch_request
    rv = self.dispatch_request()
  File "d:\documents\udacity\full stack\projects\fyyur\env\lib\site-packages\flask\app.py", line 1485, in dispatch_request
    return self.ensure_sync(self.view_functions[rule.endpoint])(**req.view_args)
  File "D:\Documents\Udacity\Full Stack\projects\fyyur\app.py", line 118, in venues
    data[len(data) - 1]["venues"].append({
IndexError: list index out of range
2021-05-23 12:04:49,692 INFO: errors [in D:\Documents\Udacity\Full Stack\projects\fyyur\app.py:543]
